Traceback (most recent call last):
  File "/usr/local/lib/python3.11/urllib/request.py", line 1348, in do_open
    h.request(req.get_method(), req.selector, req.data, headers,
  File "/usr/local/lib/python3.11/http/client.py", line 1298, in request
    self._send_request(method, url, body, headers, encode_chunked)
  File "/usr/local/lib/python3.11/http/client.py", line 1344, in _send_request
    self.endheaders(body, encode_chunked=encode_chunked)
  File "/usr/local/lib/python3.11/http/client.py", line 1293, in endheaders
    self._send_output(message_body, encode_chunked=encode_chunked)
  File "/usr/local/lib/python3.11/http/client.py", line 1052, in _send_output
    self.send(msg)
  File "/usr/local/lib/python3.11/http/client.py", line 990, in send
    self.connect()
  File "/usr/local/lib/python3.11/http/client.py", line 1463, in connect
    super().connect()
  File "/usr/local/lib/python3.11/http/client.py", line 956, in connect
    self.sock = self._create_connection(
                ^^^^^^^^^^^^^^^^^^^^^^^^
  File "/usr/local/lib/python3.11/socket.py", line 827, in create_connection
    for res in getaddrinfo(host, port, 0, SOCK_STREAM):
               ^^^^^^^^^^^^^^^^^^^^^^^^^^^^^^^^^^^^^^^
  File "/usr/local/lib/python3.11/socket.py", line 962, in getaddrinfo
    for res in _socket.getaddrinfo(host, port, family, type, proto, flags):
               ^^^^^^^^^^^^^^^^^^^^^^^^^^^^^^^^^^^^^^^^^^^^^^^^^^^^^^^^^^^
socket.gaierror: [Errno -3] Temporary failure in name resolution

During handling of the above exception, another exception occurred:

Traceback (most recent call last):
  File "/mnt/data/linear_regression_project/src/linear_regression.py", line 128, in <module>
    main()
  File "/mnt/data/linear_regression_project/src/linear_regression.py", line 120, in main
    df = load_default()
         ^^^^^^^^^^^^^^
  File "/mnt/data/linear_regression_project/src/linear_regression.py", line 21, in load_default
    data = fetch_california_housing(as_frame=True)
           ^^^^^^^^^^^^^^^^^^^^^^^^^^^^^^^^^^^^^^^
  File "/home/sandbox/.local/lib/python3.11/site-packages/sklearn/datasets/_california_housing.py", line 138, in fetch_california_housing
    archive_path = _fetch_remote(ARCHIVE, dirname=data_home)
                   ^^^^^^^^^^^^^^^^^^^^^^^^^^^^^^^^^^^^^^^^^
  File "/home/sandbox/.local/lib/python3.11/site-packages/sklearn/datasets/_base.py", line 1511, in _fetch_remote
    urlretrieve(remote.url, file_path)
  File "/usr/local/lib/python3.11/urllib/request.py", line 241, in urlretrieve
    with contextlib.closing(urlopen(url, data)) as fp:
                            ^^^^^^^^^^^^^^^^^^
  File "/usr/local/lib/python3.11/urllib/request.py", line 216, in urlopen
    return opener.open(url, data, timeout)
           ^^^^^^^^^^^^^^^^^^^^^^^^^^^^^^^
  File "/usr/local/lib/python3.11/urllib/request.py", line 519, in open
    response = self._open(req, data)
               ^^^^^^^^^^^^^^^^^^^^^
  File "/usr/local/lib/python3.11/urllib/request.py", line 536, in _open
    result = self._call_chain(self.handle_open, protocol, protocol +
             ^^^^^^^^^^^^^^^^^^^^^^^^^^^^^^^^^^^^^^^^^^^^^^^^^^^^^^^
  File "/usr/local/lib/python3.11/urllib/request.py", line 496, in _call_chain
    result = func(*args)
             ^^^^^^^^^^^
  File "/usr/local/lib/python3.11/urllib/request.py", line 1391, in https_open
    return self.do_open(http.client.HTTPSConnection, req,
           ^^^^^^^^^^^^^^^^^^^^^^^^^^^^^^^^^^^^^^^^^^^^^^
  File "/usr/local/lib/python3.11/urllib/request.py", line 1351, in do_open
    raise URLError(err)
urllib.error.URLError: <urlopen error [Errno -3] Temporary failure in name resolution>
